<!DOCTYPE html>
<html lang="en">
<head>
    <meta charset="UTF-8">
    <meta http-equiv="X-UA-Compatible" content="IE=edge">
    <meta name="viewport" content="width=device-width, initial-scale=1.0">
    <link rel="stylesheet" href="../../styles.css">
    <title>Обработка ошибок</title>
</head>
<body>
    <div class="learn-page__layout">
        <h1><a href="../../1_module/">Back to module 1</a></h1>
        <section class="learn-page__layout--study-block">
            <h3>Обозначения:</h3>
            <div class="text checked">Зеленый блок = прогресс изучения; Зеленая рамка = повторил, классно.</div>
            <div class="help helpful">Синий блок = полезная подсказка; Синяя рамка = очень важно, очень классно.</div>
            <div class="script useless">Красный блок = задача; Красная рамка = на мой взгляд не стоит внимания.</div>
        </section>
        <section class="learn-page__layout--study-block">
            <h3>10.1 Обработка ошибок, "try..catch"</h3>
            <div class="text">
                <b>Синтаксис «try…catch»</b>
                <p>
                    1) Сначала выполняется код внутри блока try {...}.<br><br>
                    2) Если в нём нет ошибок, то блок catch(err) игнорируется: выполнение доходит до конца try и потом далее, полностью пропуская catch.<br><br>
                    3) Если же в нём возникает ошибка, то выполнение try прерывается, и поток управления переходит в начало catch(err). 
                </p>
            </div>
            <div class="help">
                <b>Объект ошибки</b>
                <p>
                    Когда возникает ошибка, JavaScript генерирует объект, содержащий её детали. Затем этот объект передаётся как аргумент в блок catch:<br><br>
                    1) name: Имя ошибки. Например, для неопределённой переменной это "ReferenceError".<br><br>
                    2) message: Текстовое сообщение о деталях ошибки. <br><br>
                    3) stack. Текущий стек вызова: строка, содержащая информацию о последовательности вложенных вызовов, которые привели к ошибке. Используется в целях отладки.
                </p>
            </div>
            <div class="help">
                <b>Генерация собственных ошибок</b>
                <p>
                    Оператор throw генерирует ошибку. Синтаксис: throw {объект ошибки}. Пример: let error = new Error(message);
                </p>
            </div>
            <div class="help">
                <b>Проброс исключения</b>
                <p>
                    Блок catch должен обрабатывать только те ошибки, которые ему известны, и «пробрасывать» все остальные. <br><br>
                    Техника «проброс исключения» выглядит так: <br><br>
                    1) Блок catch получает все ошибки. <br><br>
                    2) В блоке catch(err) {...} мы анализируем объект ошибки err. <br><br>
                    3) Если мы не знаем как её обработать, тогда делаем throw err.
                </p>
            </div>
            <div class="text">
                <b>try…catch…finally</b>
                <p>
                    Конструкция try..catch может содержать ещё одну секцию: finally.<br><br>
                    Если секция есть, то она выполняется в любом случае: после try, если не было ошибок, после catch, если ошибки были.
                </p>
            </div>
            <div class="script">
                <b>Задачи. Finally или просто код?</b>
                <p>
                    <code>
                        Различным. Если используем return, можем выйти до обработки ошибок, но если есть finally, то всё равно в него заглянем после return.
                    </code>
                </p>
            </div>
        </section>
        <section class="learn-page__layout--study-block">
            <h3>10.2 Пользовательские ошибки, расширение Error</h3>
            <div class="text">
                <b>Ответ на вопрос "а зачем?"</b>
                <p>
                    Когда что-то разрабатываем, то нам часто необходимы собственные классы ошибок для разных вещей, которые могут пойти не так в наших задачах. 
                    Для ошибок при работе с сетью может понадобиться HttpError, для операций с базой данных DbError, для поиска – NotFoundError и т.д. <br><br>
                    Наши ошибки должны поддерживать базовые свойства, такие как message, name и, желательно, stack. Но также они могут иметь свои собственные свойства. 
                    Например, объекты HttpError могут иметь свойство statusCode со значениями 404, 403 или 500.
                </p>
            </div>
            <div class="text">
                <b>Расширение Error</b>
                <p>
                    Класс Error встроенный, вот его примерный код, просто чтобы мы понимали, что расширяем:
                </p>
                <img src="./img/1.png" alt="" width="100%">
                <p>
                    Вот как это работает: (Я бы мб создал функцию validateError с этими if, в отдельном файле).
                </p>
                <img src="./img/2.png" alt="" width="100%">
            </div>
            <div class="text">
                <b>Обёртывание исключений</b>
                <p>
                    Обёртывание исключений является распространённой техникой: функция ловит низкоуровневые исключения и 
                    создаёт одно «высокоуровневое» исключение вместо разных низкоуровневых.
                </p>
            </div>
            <div class="script">
                <b>Задачи. Наследование от SyntaxError</b>
                <p>
                    <code>
                        class FormatError extends SyntaxError {
                            constructor(message) {
                                super(message);
                                this.name = "FormatError";
                            }
                        }
                    </code>
                </p>
            </div>
        </section>
    </div>
</body>
</html>